2025-03-24 11:48:58,441 - crypto_prediction - INFO - Starting visualization dashboard on 0.0.0.0:8050
2025-03-24 11:48:58,441 - crypto_prediction - INFO - Starting visualization dashboard on 0.0.0.0:8050
2025-03-24 11:48:58,441 - crypto_prediction - INFO - Application started
2025-03-24 11:48:58,441 - crypto_prediction - INFO - Application started
2025-03-24 11:48:58,441 - crypto_prediction - WARNING - Warning message
2025-03-24 11:48:58,441 - crypto_prediction - WARNING - Warning message
2025-03-24 11:48:58,441 - crypto_prediction - ERROR - Error message
2025-03-24 11:48:58,441 - crypto_prediction - ERROR - Error message
2025-03-24 11:50:18,143 - crypto_prediction - INFO - Starting visualization dashboard on 0.0.0.0:8050
2025-03-24 11:50:18,143 - crypto_prediction - INFO - Starting visualization dashboard on 0.0.0.0:8050
2025-03-24 11:50:18,143 - crypto_prediction - INFO - Application started
2025-03-24 11:50:18,143 - crypto_prediction - INFO - Application started
2025-03-24 11:50:18,143 - crypto_prediction - WARNING - Warning message
2025-03-24 11:50:18,143 - crypto_prediction - WARNING - Warning message
2025-03-24 11:50:18,143 - crypto_prediction - ERROR - Error message
2025-03-24 11:50:18,143 - crypto_prediction - ERROR - Error message
2025-03-24 11:50:38,659 - crypto_prediction - ERROR - Error fetching cryptocurrencies: HTTPConnectionPool(host='0.0.0.0', port=8000): Max retries exceeded with url: /cryptocurrencies (Caused by NewConnectionError('<urllib3.connection.HTTPConnection object at 0x0000014E8011E310>: Failed to establish a new connection: [WinError 10049] The requested address is not valid in its context'))
2025-03-24 11:50:38,659 - crypto_prediction - ERROR - Error fetching cryptocurrencies: HTTPConnectionPool(host='0.0.0.0', port=8000): Max retries exceeded with url: /cryptocurrencies (Caused by NewConnectionError('<urllib3.connection.HTTPConnection object at 0x0000014E8011E310>: Failed to establish a new connection: [WinError 10049] The requested address is not valid in its context'))
2025-03-24 11:50:38,675 - crypto_prediction - ERROR - Error fetching models: HTTPConnectionPool(host='0.0.0.0', port=8000): Max retries exceeded with url: /models (Caused by NewConnectionError('<urllib3.connection.HTTPConnection object at 0x0000014E80345350>: Failed to establish a new connection: [WinError 10049] The requested address is not valid in its context'))
2025-03-24 11:50:38,675 - crypto_prediction - ERROR - Error fetching models: HTTPConnectionPool(host='0.0.0.0', port=8000): Max retries exceeded with url: /models (Caused by NewConnectionError('<urllib3.connection.HTTPConnection object at 0x0000014E80345350>: Failed to establish a new connection: [WinError 10049] The requested address is not valid in its context'))
2025-03-24 13:08:02,551 - crypto_prediction - INFO - Starting visualization dashboard on 0.0.0.0:8050
2025-03-24 13:08:02,551 - crypto_prediction - INFO - Starting visualization dashboard on 0.0.0.0:8050
2025-03-24 13:08:02,551 - crypto_prediction - INFO - Application started
2025-03-24 13:08:02,551 - crypto_prediction - INFO - Application started
2025-03-24 13:08:02,551 - crypto_prediction - WARNING - Warning message
2025-03-24 13:08:02,551 - crypto_prediction - WARNING - Warning message
2025-03-24 13:08:02,567 - crypto_prediction - ERROR - Error message
2025-03-24 13:08:02,567 - crypto_prediction - ERROR - Error message
2025-03-24 13:08:48,466 - crypto_prediction - ERROR - Error fetching cryptocurrencies: HTTPConnectionPool(host='0.0.0.0', port=8000): Max retries exceeded with url: /cryptocurrencies (Caused by NewConnectionError('<urllib3.connection.HTTPConnection object at 0x0000026AEF06C9D0>: Failed to establish a new connection: [WinError 10049] The requested address is not valid in its context'))
2025-03-24 13:08:48,466 - crypto_prediction - ERROR - Error fetching models: HTTPConnectionPool(host='0.0.0.0', port=8000): Max retries exceeded with url: /models (Caused by NewConnectionError('<urllib3.connection.HTTPConnection object at 0x0000026AEE660410>: Failed to establish a new connection: [WinError 10049] The requested address is not valid in its context'))
2025-03-24 13:08:48,466 - crypto_prediction - ERROR - Error fetching cryptocurrencies: HTTPConnectionPool(host='0.0.0.0', port=8000): Max retries exceeded with url: /cryptocurrencies (Caused by NewConnectionError('<urllib3.connection.HTTPConnection object at 0x0000026AEF06C9D0>: Failed to establish a new connection: [WinError 10049] The requested address is not valid in its context'))
2025-03-24 13:08:48,466 - crypto_prediction - ERROR - Error fetching models: HTTPConnectionPool(host='0.0.0.0', port=8000): Max retries exceeded with url: /models (Caused by NewConnectionError('<urllib3.connection.HTTPConnection object at 0x0000026AEE660410>: Failed to establish a new connection: [WinError 10049] The requested address is not valid in its context'))
2025-03-24 13:09:20,853 - crypto_prediction - INFO - Starting test suite for cryptocurrency price prediction system
2025-03-24 13:09:20,853 - crypto_prediction - INFO - Starting test suite for cryptocurrency price prediction system
2025-03-24 13:09:50,900 - crypto_prediction - ERROR - Tests failed: [(<tests.test_system.TestDataCollection testMethod=test_get_historical_data>, 'Traceback (most recent call last):\n  File "C:\\Users\\larri\\Documents\\crypto-research\\crypto_prediction\\tests\\test_system.py", line 70, in test_get_historical_data\n    self.assertIn(col, df.columns, f"Missing column {col} in historical data")\nAssertionError: \'open\' not found in Index([\'close\', \'volume\', \'market_cap\'], dtype=\'object\') : Missing column open in historical data\n'), (<tests.test_system.TestDataCollection testMethod=test_save_and_load_data>, 'Traceback (most recent call last):\n  File "C:\\Users\\larri\\Documents\\crypto-research\\crypto_prediction\\tests\\test_system.py", line 105, in test_save_and_load_data\n    self.assertTrue(os.path.exists(filename), f"Data file {filename} not created")\nAssertionError: False is not true : Data file data/test\\btc_1d.csv not created\n'), (<tests.test_system.TestDataPreprocessing testMethod=test_add_technical_indicators>, 'Traceback (most recent call last):\n  File "C:\\Users\\larri\\Documents\\crypto-research\\crypto_prediction\\tests\\test_system.py", line 157, in test_add_technical_indicators\n    self.assertFalse(indicators_df.empty, "Data with indicators is empty")\nAssertionError: True is not false : Data with indicators is empty\n'), (<tests.test_system.TestDataPreprocessing testMethod=test_clean_data>, 'Traceback (most recent call last):\n  File "C:\\Users\\larri\\Documents\\crypto-research\\crypto_prediction\\tests\\test_system.py", line 138, in test_clean_data\n    self.assertFalse(cleaned_df.empty, "Cleaned data is empty")\nAssertionError: True is not false : Cleaned data is empty\n'), (<tests.test_system.TestDataPreprocessing testMethod=test_normalize_features>, 'Traceback (most recent call last):\n  File "C:\\Users\\larri\\Documents\\crypto-research\\crypto_prediction\\tests\\test_system.py", line 175, in test_normalize_features\n    self.assertFalse(normalized_df.empty, "Normalized data is empty")\nAssertionError: True is not false : Normalized data is empty\n'), (<tests.test_system.TestDataPreprocessing testMethod=test_prepare_sequences>, 'Traceback (most recent call last):\n  File "C:\\Users\\larri\\Documents\\crypto-research\\crypto_prediction\\tests\\test_system.py", line 196, in test_prepare_sequences\n    self.assertIsNotNone(X, "X sequences are None")\nAssertionError: unexpectedly None : X sequences are None\n')] failures, [(<tests.test_system.TestDataCollection testMethod=test_api_connection>, 'Traceback (most recent call last):\n  File "C:\\Users\\larri\\Documents\\crypto-research\\crypto_prediction\\tests\\test_system.py", line 43, in test_api_connection\n    result = self.collector.test_api_connection(\'coingecko\')\n             ^^^^^^^^^^^^^^^^^^^^^^^^^^^^^^^^^^\nAttributeError: \'DataCollector\' object has no attribute \'test_api_connection\'\n'), (<tests.test_system.TestModelTraining testMethod=test_bilstm_model>, 'Traceback (most recent call last):\n  File "C:\\Users\\larri\\Documents\\crypto-research\\crypto_prediction\\tests\\test_system.py", line 231, in setUp\n    train_size = int(0.7 * len(X))\n                           ^^^^^^\nTypeError: object of type \'NoneType\' has no len()\n'), (<tests.test_system.TestModelTraining testMethod=test_xgboost_model>, 'Traceback (most recent call last):\n  File "C:\\Users\\larri\\Documents\\crypto-research\\crypto_prediction\\tests\\test_system.py", line 231, in setUp\n    train_size = int(0.7 * len(X))\n                           ^^^^^^\nTypeError: object of type \'NoneType\' has no len()\n')] errors
2025-03-24 13:09:50,900 - crypto_prediction - ERROR - Tests failed: [(<tests.test_system.TestDataCollection testMethod=test_get_historical_data>, 'Traceback (most recent call last):\n  File "C:\\Users\\larri\\Documents\\crypto-research\\crypto_prediction\\tests\\test_system.py", line 70, in test_get_historical_data\n    self.assertIn(col, df.columns, f"Missing column {col} in historical data")\nAssertionError: \'open\' not found in Index([\'close\', \'volume\', \'market_cap\'], dtype=\'object\') : Missing column open in historical data\n'), (<tests.test_system.TestDataCollection testMethod=test_save_and_load_data>, 'Traceback (most recent call last):\n  File "C:\\Users\\larri\\Documents\\crypto-research\\crypto_prediction\\tests\\test_system.py", line 105, in test_save_and_load_data\n    self.assertTrue(os.path.exists(filename), f"Data file {filename} not created")\nAssertionError: False is not true : Data file data/test\\btc_1d.csv not created\n'), (<tests.test_system.TestDataPreprocessing testMethod=test_add_technical_indicators>, 'Traceback (most recent call last):\n  File "C:\\Users\\larri\\Documents\\crypto-research\\crypto_prediction\\tests\\test_system.py", line 157, in test_add_technical_indicators\n    self.assertFalse(indicators_df.empty, "Data with indicators is empty")\nAssertionError: True is not false : Data with indicators is empty\n'), (<tests.test_system.TestDataPreprocessing testMethod=test_clean_data>, 'Traceback (most recent call last):\n  File "C:\\Users\\larri\\Documents\\crypto-research\\crypto_prediction\\tests\\test_system.py", line 138, in test_clean_data\n    self.assertFalse(cleaned_df.empty, "Cleaned data is empty")\nAssertionError: True is not false : Cleaned data is empty\n'), (<tests.test_system.TestDataPreprocessing testMethod=test_normalize_features>, 'Traceback (most recent call last):\n  File "C:\\Users\\larri\\Documents\\crypto-research\\crypto_prediction\\tests\\test_system.py", line 175, in test_normalize_features\n    self.assertFalse(normalized_df.empty, "Normalized data is empty")\nAssertionError: True is not false : Normalized data is empty\n'), (<tests.test_system.TestDataPreprocessing testMethod=test_prepare_sequences>, 'Traceback (most recent call last):\n  File "C:\\Users\\larri\\Documents\\crypto-research\\crypto_prediction\\tests\\test_system.py", line 196, in test_prepare_sequences\n    self.assertIsNotNone(X, "X sequences are None")\nAssertionError: unexpectedly None : X sequences are None\n')] failures, [(<tests.test_system.TestDataCollection testMethod=test_api_connection>, 'Traceback (most recent call last):\n  File "C:\\Users\\larri\\Documents\\crypto-research\\crypto_prediction\\tests\\test_system.py", line 43, in test_api_connection\n    result = self.collector.test_api_connection(\'coingecko\')\n             ^^^^^^^^^^^^^^^^^^^^^^^^^^^^^^^^^^\nAttributeError: \'DataCollector\' object has no attribute \'test_api_connection\'\n'), (<tests.test_system.TestModelTraining testMethod=test_bilstm_model>, 'Traceback (most recent call last):\n  File "C:\\Users\\larri\\Documents\\crypto-research\\crypto_prediction\\tests\\test_system.py", line 231, in setUp\n    train_size = int(0.7 * len(X))\n                           ^^^^^^\nTypeError: object of type \'NoneType\' has no len()\n'), (<tests.test_system.TestModelTraining testMethod=test_xgboost_model>, 'Traceback (most recent call last):\n  File "C:\\Users\\larri\\Documents\\crypto-research\\crypto_prediction\\tests\\test_system.py", line 231, in setUp\n    train_size = int(0.7 * len(X))\n                           ^^^^^^\nTypeError: object of type \'NoneType\' has no len()\n')] errors
2025-03-24 13:16:36,677 - crypto_prediction - INFO - Starting deployment of cryptocurrency price prediction system using systemd
2025-03-24 13:16:36,738 - crypto_prediction - INFO - Created systemd service files in deployment/systemd
2025-03-24 13:16:36,742 - crypto_prediction - INFO - Created deployment documentation at deployment/docs\deployment_guide.md
2025-03-24 13:16:36,742 - crypto_prediction - INFO - Deployment preparation completed successfully
2025-03-24 13:18:22,020 - crypto_prediction - INFO - Starting visualization dashboard on 0.0.0.0:8050
2025-03-24 13:18:22,020 - crypto_prediction - INFO - Starting visualization dashboard on 0.0.0.0:8050
2025-03-24 13:18:22,020 - crypto_prediction - INFO - Application started
2025-03-24 13:18:22,020 - crypto_prediction - INFO - Application started
2025-03-24 13:18:22,020 - crypto_prediction - WARNING - Warning message
2025-03-24 13:18:22,020 - crypto_prediction - WARNING - Warning message
2025-03-24 13:18:22,020 - crypto_prediction - ERROR - Error message
2025-03-24 13:18:22,020 - crypto_prediction - ERROR - Error message
2025-03-24 13:18:34,651 - crypto_prediction - ERROR - Error fetching models: HTTPConnectionPool(host='0.0.0.0', port=8000): Max retries exceeded with url: /models (Caused by NewConnectionError('<urllib3.connection.HTTPConnection object at 0x000001CCDA886290>: Failed to establish a new connection: [WinError 10049] The requested address is not valid in its context'))
2025-03-24 13:18:34,651 - crypto_prediction - ERROR - Error fetching cryptocurrencies: HTTPConnectionPool(host='0.0.0.0', port=8000): Max retries exceeded with url: /cryptocurrencies (Caused by NewConnectionError('<urllib3.connection.HTTPConnection object at 0x000001CCDA69BE10>: Failed to establish a new connection: [WinError 10049] The requested address is not valid in its context'))
2025-03-24 13:18:34,651 - crypto_prediction - ERROR - Error fetching models: HTTPConnectionPool(host='0.0.0.0', port=8000): Max retries exceeded with url: /models (Caused by NewConnectionError('<urllib3.connection.HTTPConnection object at 0x000001CCDA886290>: Failed to establish a new connection: [WinError 10049] The requested address is not valid in its context'))
2025-03-24 13:18:34,651 - crypto_prediction - ERROR - Error fetching cryptocurrencies: HTTPConnectionPool(host='0.0.0.0', port=8000): Max retries exceeded with url: /cryptocurrencies (Caused by NewConnectionError('<urllib3.connection.HTTPConnection object at 0x000001CCDA69BE10>: Failed to establish a new connection: [WinError 10049] The requested address is not valid in its context'))
2025-03-24 13:18:48,738 - crypto_prediction - ERROR - Error fetching cryptocurrencies: HTTPConnectionPool(host='0.0.0.0', port=8000): Max retries exceeded with url: /cryptocurrencies (Caused by NewConnectionError('<urllib3.connection.HTTPConnection object at 0x000001CCDA893BD0>: Failed to establish a new connection: [WinError 10049] The requested address is not valid in its context'))
2025-03-24 13:18:48,738 - crypto_prediction - ERROR - Error fetching models: HTTPConnectionPool(host='0.0.0.0', port=8000): Max retries exceeded with url: /models (Caused by NewConnectionError('<urllib3.connection.HTTPConnection object at 0x000001CCDA883F50>: Failed to establish a new connection: [WinError 10049] The requested address is not valid in its context'))
2025-03-24 13:18:48,738 - crypto_prediction - ERROR - Error fetching cryptocurrencies: HTTPConnectionPool(host='0.0.0.0', port=8000): Max retries exceeded with url: /cryptocurrencies (Caused by NewConnectionError('<urllib3.connection.HTTPConnection object at 0x000001CCDA893BD0>: Failed to establish a new connection: [WinError 10049] The requested address is not valid in its context'))
2025-03-24 13:18:48,738 - crypto_prediction - ERROR - Error fetching models: HTTPConnectionPool(host='0.0.0.0', port=8000): Max retries exceeded with url: /models (Caused by NewConnectionError('<urllib3.connection.HTTPConnection object at 0x000001CCDA883F50>: Failed to establish a new connection: [WinError 10049] The requested address is not valid in its context'))
2025-03-24 13:19:18,273 - crypto_prediction - INFO - Starting data collection pipeline
2025-03-24 13:19:19,212 - crypto_prediction.data.data_collection - INFO - Collecting data for BTC
2025-03-24 13:19:20,297 - crypto_prediction.data.data_collection - ERROR - API request failed: 401 Client Error: Unauthorized for url: https://api.coingecko.com/api/v3/coins/osmosis-allbtc/market_chart?vs_currency=usd&days=730&interval=daily
2025-03-24 13:19:20,297 - crypto_prediction.data.data_collection - ERROR - Failed to get historical data for BTC
2025-03-24 13:19:20,313 - crypto_prediction.data.data_collection - WARNING - No data collected for BTC
2025-03-24 13:19:20,318 - crypto_prediction.data.data_collection - INFO - Collecting data for ETH
2025-03-24 13:19:21,489 - crypto_prediction.data.data_collection - ERROR - API request failed: 401 Client Error: Unauthorized for url: https://api.coingecko.com/api/v3/coins/the-ticker-is-eth/market_chart?vs_currency=usd&days=730&interval=daily
2025-03-24 13:19:21,502 - crypto_prediction.data.data_collection - ERROR - Failed to get historical data for ETH
2025-03-24 13:19:21,506 - crypto_prediction.data.data_collection - WARNING - No data collected for ETH
2025-03-24 13:19:21,506 - crypto_prediction.data.data_collection - INFO - Collecting data for BNB
2025-03-24 13:19:22,727 - crypto_prediction.data.data_collection - ERROR - API request failed: 401 Client Error: Unauthorized for url: https://api.coingecko.com/api/v3/coins/binance-coin-wormhole/market_chart?vs_currency=usd&days=730&interval=daily
2025-03-24 13:19:22,727 - crypto_prediction.data.data_collection - ERROR - Failed to get historical data for BNB
2025-03-24 13:19:22,727 - crypto_prediction.data.data_collection - WARNING - No data collected for BNB
2025-03-24 13:19:22,727 - crypto_prediction.data.data_collection - INFO - Collecting data for SOL
